Workbook

Sheet Respondents (Table 1)
A1: Table 1
A2: Distribution of Research Respondents
A3: Respondent Category | B3: Frequency | C3: Percentage | D3: Recorded in Workbook | E3: Check
A4: IT Experts | B4: 5 | C4: =B4/$B$8 -> 0.14285714 | D4: =COUNTA('IT Experts'!C5:G5) -> 5 | E4: =IF(D4=B4,"OK","Check") -> OK
A5: TODA Officials (Super Admin/Admin) | B5: 3 | C5: =B5/$B$8 -> 0.085714286 | D5: =COUNTA('End-Users'!C5:AF5) -> 30 | E5: =IF(D5=SUM(B5:B7),"OK","Check") -> OK
A6: Official TODA Drivers | B6: 12 | C6: =B6/$B$8 -> 0.34285714
A7: Santa Rosa Homes Residents | B7: 15 | C7: =B7/$B$8 -> 0.42857143
A8: Total | B8: =SUM(B4:B7) -> 35 | C8: =SUM(C4:C7) -> 1 | D8: =D4+D5 -> 35 | E8: =IF(D8=B8,"OK","Check") -> OK
A9: Note. N = 35. Percentage = frequency ÷ total respondents. "Recorded in Workbook" counts the respondent columns in the IT Experts (R1–R5) and End-Users (R1–R30: TODA Officials, Drivers, and Residents) sheets and should match the frequencies above.

Sheet Scoring Rubrics
A1: Scoring Rubrics and Rating Scales — SRH LINK-TODA (from Chapter 2 and Appendix B)
A2: Weighted means in the APA Results sheets are interpreted with these ranges. Edit a remark here and every table that uses it updates automatically.
A4: Table 2. Scoring Rubric for Functional Suitability
A5: Lower limit of weighted mean | B5: Range | C5: Qualitative Remarks | D5: Verbal Description
A6: 4.21 | B6: 4.21 – 5.00 | C6: Highly Suitable | D6: The SRH LINK-TODA meets or exceeds all functional requirements with high accuracy, completeness, and efficiency.
A7: 3.41 | B7: 3.41 – 4.20 | C7: Suitable | D7: The SRH LINK-TODA meets most functional requirements with a satisfactory level of accuracy, completeness, and efficiency.
A8: 2.61 | B8: 2.61 – 3.40 | C8: Somewhat Suitable | D8: The SRH LINK-TODA meets some functional requirements but demonstrates low levels of accuracy, completeness, or efficiency.
A9: 1.81 | B9: 1.81 – 2.60 | C9: Unsuitable | D9: The SRH LINK-TODA meets very few functional requirements, with low accuracy, completeness, and efficiency.
A10: 1 | B10: 1.00 – 1.80 | C10: Highly Unsuitable | D10: The SRH LINK-TODA fails to meet most, if not all, functional requirements, with very low accuracy, completeness, and efficiency.
A12: Table 3. Scoring Rubric for Performance Efficiency
A13: Lower limit of weighted mean | B13: Range | C13: Qualitative Remarks | D13: Verbal Description
A14: 4.21 | B14: 4.21 – 5.00 | C14: Highly Efficient | D14: The SRH LINK-TODA’s performance is exceptional, meeting or exceeding all efficiency requirements. Users experience no delays or errors, and the system performs consistently well under all operating conditions.
A15: 3.41 | B15: 3.41 – 4.20 | C15: Efficient | D15: The SRH LINK-TODA’s performance is above average and meets most efficiency requirements. Users experience minimal delays or errors, and the system performs well under normal operating conditions.
A16: 2.61 | B16: 2.61 – 3.40 | C16: Less Efficient | D16: The SRH LINK-TODA’s performance is average, with room for improvement. Users may experience occasional delays or errors, but overall, the system functions adequately.
A17: 1.81 | B17: 1.81 – 2.60 | C17: Inefficient | D17: The SRH LINK-TODA’s performance is below average and fails to fully meet efficiency requirements. Users may experience delays or errors that affect productivity.
A18: 1 | B18: 1.00 – 1.80 | C18: Highly Inefficient | D18: The SRH LINK-TODA’s performance is significantly below expectations, frequently causing delays, errors, or failures that disrupt normal operation.
A20: Table 4. Scoring Rubric for Compatibility
A21: Lower limit of weighted mean | B21: Range | C21: Qualitative Remarks | D21: Verbal Description
A22: 4.21 | B22: 4.21 – 5.00 | C22: Highly Compatible | D22: The SRH LINK-TODA is fully compatible with other hardware or software and can seamlessly integrate without any issues or modifications.
A23: 3.41 | B23: 3.41 – 4.20 | C23: Compatible | D23: The SRH LINK-TODA can work with other hardware or software with minor adjustments or configurations.
A24: 2.61 | B24: 2.61 – 3.40 | C24: Somewhat Compatible | D24: The SRH LINK-TODA can work with other hardware or software, but requires significant adjustments or configurations.
A25: 1.81 | B25: 1.81 – 2.60 | C25: Less Compatible | D25: The SRH LINK-TODA struggles to integrate with other hardware or software and requires significant adjustments.
A26: 1 | B26: 1.00 – 1.80 | C26: Not Compatible | D26: The SRH LINK-TODA cannot work with other hardware or software and requires a complete redesign or replacement.
A28: Table 5. Scoring Rubric for Interaction Capability
A29: Lower limit of weighted mean | B29: Range | C29: Qualitative Remarks | D29: Verbal Description
A30: 4.21 | B30: 4.21 – 5.00 | C30: Highly Interactive | D30: Users can perform tasks intuitively and efficiently, with smooth system responses and clear, immediate feedback.
A31: 3.41 | B31: 3.41 – 4.20 | C31: Interactive | D31: Users can perform tasks with some guidance or minor delays; system feedback is generally adequate.
A32: 2.61 | B32: 2.61 – 3.40 | C32: Less Interactive | D32: Users face difficulties interacting with the system, with delays or unclear feedback reducing task efficiency.
A33: 1.81 | B33: 1.81 – 2.60 | C33: Poorly Interactive | D33: Users experience significant difficulties with delayed responses and confusing feedback.
A34: 1 | B34: 1.00 – 1.80 | C34: Non-Interactive | D34: Users cannot effectively interact with the system due to poor responsiveness, unclear instructions, or system errors.
A36: Table 6. Scoring Rubric for Reliability
A37: Lower limit of weighted mean | B37: Range | C37: Qualitative Remarks | D37: Verbal Description
A38: 4.21 | B38: 4.21 – 5.00 | C38: Highly Reliable | D38: The SRH LINK-TODA operates consistently without failures, delivering accurate, dependable outcomes under all conditions.
A39: 3.41 | B39: 3.41 – 4.20 | C39: Reliable | D39: The SRH LINK-TODA generally operates as expected, with only minor or occasional errors.
A40: 2.61 | B40: 2.61 – 3.40 | C40: Slightly Reliable | D40: The SRH LINK-TODA is prone to errors or interruptions, affecting performance and dependability.
A41: 1.81 | B41: 1.81 – 2.60 | C41: Unreliable | D41: The SRH LINK-TODA frequently experiences errors or interruptions, reducing overall dependability.
A42: 1 | B42: 1.00 – 1.80 | C42: Non-Reliable | D42: The SRH LINK-TODA frequently fails or produces inaccurate results, making it unreliable for its intended use.
A44: Table 7. Scoring Rubric for Security
A45: Lower limit of weighted mean | B45: Range | C45: Qualitative Remarks | D45: Verbal Description
A46: 4.21 | B46: 4.21 – 5.00 | C46: Strong Security | D46: The SRH LINK-TODA has multiple layers of security measures that provide comprehensive protection against unauthorized access, data breaches, and other threats. Security features are regularly updated and tested to ensure effectiveness.
...

Sheet IT Experts
A1: Assessment on the Technical Aspect of the System (ISO/IEC 25010:2023) — For IT Experts
A2: Scale: 5 = Highly Suitable/Efficient (HS) | 4 = Suitable/Efficient (S) | 3 = Moderately Suitable (MS) | 2 = Unsuitable/Inefficient (U) | 1 = Highly Unsuitable (HU)
A3: Editable cells: yellow-shaded respondent score cells (R1–R5). Enter values 1–5 only. Sample data shown below. Add columns between R4 and R5 if respondents is greater than 5.
A5: Item No. | B5: Item Statement | C5: R1 | D5: R2 | E5: R3 | F5: R4 | G5: R5 | H5: Weighted Mean | I5: HS (5) | J5: S (4) | K5: MS (3) | L5: U (2) | M5: HU (1)
A6: Functional Suitability — The degree to which the system provides functions that meet stated and implied needs when used under specified conditions.
A7: 1 | B7: The 35-meter geofencing triggers accurately log driver terminal entries and exits while deactivating coordinate tracking during active transit. | C7: 5 | D7: 5 | E7: 5 | F7: 5 | G7: 5 | H7: =(5*I7+4*J7+3*K7+2*L7+1*M7)/SUM(I7:M7) -> 5 | I7: =COUNTIF(C7:G7,5) -> 5 | J7: =COUNTIF(C7:G7,4) -> 0 | K7: =COUNTIF(C7:G7,3) -> 0 | L7: =COUNTIF(C7:G7,2) -> 0 | M7: =COUNTIF(C7:G7,1) -> 0
A8: 2 | B8: The priority-based queue algorithm accurately sequences drivers in first-in, first-served order and immediately recovers dispatch positions upon cancellations. | C8: 4 | D8: 5 | E8: 5 | F8: 5 | G8: 5 | H8: =(5*I8+4*J8+3*K8+2*L8+1*M8)/SUM(I8:M8) -> 4.8 | I8: =COUNTIF(C8:G8,5) -> 4 | J8: =COUNTIF(C8:G8,4) -> 1 | K8: =COUNTIF(C8:G8,3) -> 0 | L8: =COUNTIF(C8:G8,2) -> 0 | M8: =COUNTIF(C8:G8,1) -> 0
A9: 3 | B9: The TODA Admin and Super Admin dashboards successfully execute manual queue overrides, driver removals, and compliance verifications without corrupting the dispatch sequence. | C9: 4 | D9: 5 | E9: 5 | F9: 5 | G9: 5 | H9: =(5*I9+4*J9+3*K9+2*L9+1*M9)/SUM(I9:M9) -> 4.8 | I9: =COUNTIF(C9:G9,5) -> 4 | J9: =COUNTIF(C9:G9,4) -> 1 | K9: =COUNTIF(C9:G9,3) -> 0 | L9: =COUNTIF(C9:G9,2) -> 0 | M9: =COUNTIF(C9:G9,1) -> 0
A10: Category Weighted Mean — Functional Suitability | H10: =AVERAGE(H7:H9) -> 4.8666667
A11: Performance Efficiency — Relative to the number of resources used under stated conditions.
A12: 4 | B12: The Laravel Reverb event-driven architecture broadcasts real-time map updates and queue transitions within the acceptable latency threshold. | C12: 3 | D12: 4 | E12: 4 | F12: 4 | G12: 4 | H12: =(5*I12+4*J12+3*K12+2*L12+1*M12)/SUM(I12:M12) -> 3.8 | I12: =COUNTIF(C12:G12,5) -> 0 | J12: =COUNTIF(C12:G12,4) -> 4 | K12: =COUNTIF(C12:G12,3) -> 1 | L12: =COUNTIF(C12:G12,2) -> 0 | M12: =COUNTIF(C12:G12,1) -> 0
A13: 5 | B13: The MapLibre GL mapping engine renders hardware-accelerated vector map layers and driver positions smoothly on mobile devices. | C13: 4 | D13: 5 | E13: 4 | F13: 4 | G13: 4 | H13: =(5*I13+4*J13+3*K13+2*L13+1*M13)/SUM(I13:M13) -> 4.2 | I13: =COUNTIF(C13:G13,5) -> 1 | J13: =COUNTIF(C13:G13,4) -> 4 | K13: =COUNTIF(C13:G13,3) -> 0 | L13: =COUNTIF(C13:G13,2) -> 0 | M13: =COUNTIF(C13:G13,1) -> 0
A14: 6 | B14: The backend database queries and WebSocket listeners consume minimal server resources during peak simulated traffic. | C14: 5 | D14: 4 | E14: 4 | F14: 4 | G14: 4 | H14: =(5*I14+4*J14+3*K14+2*L14+1*M14)/SUM(I14:M14) -> 4.2 | I14: =COUNTIF(C14:G14,5) -> 1 | J14: =COUNTIF(C14:G14,4) -> 4 | K14: =COUNTIF(C14:G14,3) -> 0 | L14: =COUNTIF(C14:G14,2) -> 0 | M14: =COUNTIF(C14:G14,1) -> 0
A15: Category Weighted Mean — Performance Efficiency | H15: =AVERAGE(H12:H14) -> 4.0666667
A16: Compatibility — The degree to which a software system can exchange information with other systems whilst sharing the same software and hardware.
A17: 7 | B17: The Progressive Web Application built with the lonic Framework functions seamlessly across different mobile browsers and operating systems. | C17: 4 | D17: 3 | E17: 3 | F17: 4 | G17: 3 | H17: =(5*I17+4*J17+3*K17+2*L17+1*M17)/SUM(I17:M17) -> 3.4 | I17: =COUNTIF(C17:G17,5) -> 0 | J17: =COUNTIF(C17:G17,4) -> 2 | K17: =COUNTIF(C17:G17,3) -> 3 | L17: =COUNTIF(C17:G17,2) -> 0 | M17: =COUNTIF(C17:G17,1) -> 0
A18: 8 | B18: The system integrates well with device-level HTML5 Geolocation APIs and background Web Push notification services. | C18: 5 | D18: 5 | E18: 4 | F18: 4 | G18: 3 | H18: =(5*I18+4*J18+3*K18+2*L18+1*M18)/SUM(I18:M18) -> 4.2 | I18: =COUNTIF(C18:G18,5) -> 2 | J18: =COUNTIF(C18:G18,4) -> 2 | K18: =COUNTIF(C18:G18,3) -> 1 | L18: =COUNTIF(C18:G18,2) -> 0 | M18: =COUNTIF(C18:G18,1) -> 0
A19: 9 | B19: The user interface layout automatically adapts to varying mobile screen sizes and resolutions without visual breakage. | C19: 3 | D19: 4 | E19: 4 | F19: 4 | G19: 4 | H19: =(5*I19+4*J19+3*K19+2*L19+1*M19)/SUM(I19:M19) -> 3.8 | I19: =COUNTIF(C19:G19,5) -> 0 | J19: =COUNTIF(C19:G19,4) -> 4 | K19: =COUNTIF(C19:G19,3) -> 1 | L19: =COUNTIF(C19:G19,2) -> 0 | M19: =COUNTIF(C19:G19,1) -> 0
A20: Category Weighted Mean — Compatibility | H20: =AVERAGE(H17:H19) -> 3.8
A21: Interaction Capability — The degree to which a system can be interacted with by specified users to exchange information through the user interface to complete the intended task.
A22: 10 | B22: The user interfaces for the passenger, driver, TODA admin, and super admin portals are intuitive and easy to navigate. | C22: 5 | D22: 4 | E22: 5 | F22: 3 | G22: 4 | H22: =(5*I22+4*J22+3*K22+2*L22+1*M22)/SUM(I22:M22) -> 4.2 | I22: =COUNTIF(C22:G22,5) -> 2 | J22: =COUNTIF(C22:G22,4) -> 2 | K22: =COUNTIF(C22:G22,3) -> 1 | L22: =COUNTIF(C22:G22,2) -> 0 | M22: =COUNTIF(C22:G22,1) -> 0
A23: 11 | B23: The system provides clear and immediate visual and audio feedback upon successful actions and dispatch events. | C23: 5 | D23: 4 | E23: 5 | F23: 4 | G23: 4 | H23: =(5*I23+4*J23+3*K23+2*L23+1*M23)/SUM(I23:M23) -> 4.4 | I23: =COUNTIF(C23:G23,5) -> 2 | J23: =COUNTIF(C23:G23,4) -> 3 | K23: =COUNTIF(C23:G23,3) -> 0 | L23: =COUNTIF(C23:G23,2) -> 0 | M23: =COUNTIF(C23:G23,1) -> 0
A24: 12 | B24: Input forms include proper validation and display clear, specific error messages when invalid data is entered. | C24: 5 | D24: 4 | E24: 5 | F24: 4 | G24: 4 | H24: =(5*I24+4*J24+3*K24+2*L24+1*M24)/SUM(I24:M24) -> 4.4 | I24: =COUNTIF(C24:G24,5) -> 2 | J24: =COUNTIF(C24:G24,4) -> 3 | K24: =COUNTIF(C24:G24,3) -> 0 | L24: =COUNTIF(C24:G24,2) -> 0 | M24: =COUNTIF(C24:G24,1) -> 0
A25: Category Weighted Mean — Interaction Capability | H25: =AVERAGE(H22:H24) -> 4.3333333
A26: Reliability — The degree to which the system performs specified functions under specified conditions for a specified period of time.
A27: 13 | B27: The system securely encrypts and stores uploaded driver documents including MTOP certificates and driver licenses. | C27: 5 | D27: 4 | E27: 4 | F27: 4 | G27: 1 | H27: =(5*I27+4*J27+3*K27+2*L27+1*M27)/SUM(I27:M27) -> 3.6 | I27: =COUNTIF(C27:G27,5) -> 1 | J27: =COUNTIF(C27:G27,4) -> 3 | K27: =COUNTIF(C27:G27,3) -> 0 | L27: =COUNTIF(C27:G27,2) -> 0 | M27: =COUNTIF(C27:G27,1) -> 1
A28: 14 | B28: Role-based access controls strictly prevent unauthorized users from viewing administrative dashboards and executing management actions. | C28: 4 | D28: 4 | E28: 5 | F28: 3 | G28: 4 | H28: =(5*I28+4*J28+3*K28+2*L28+1*M28)/SUM(I28:M28) -> 4 | I28: =COUNTIF(C28:G28,5) -> 1 | J28: =COUNTIF(C28:G28,4) -> 3 | K28: =COUNTIF(C28:G28,3) -> 1 | L28: =COUNTIF(C28:G28,2) -> 0 | M28: =COUNTIF(C28:G28,1) -> 0
A29: 15 | B29: The REST API implements token-based authentication and route middleware to prevent unauthorized endpoint access and hijacked sessions. | C29: 5 | D29: 2 | E29: 2 | F29: 2 | G29: 1 | H29: =(5*I29+4*J29+3*K29+2*L29+1*M29)/SUM(I29:M29) -> 2.4 | I29: =COUNTIF(C29:G29,5) -> 1 | J29: =COUNTIF(C29:G29,4) -> 0 | K29: =COUNTIF(C29:G29,3) -> 0 | L29: =COUNTIF(C29:G29,2) -> 3 | M29: =COUNTIF(C29:G29,1) -> 1
A30: Category Weighted Mean — Reliability | H30: =AVERAGE(H27:H29) -> 3.3333333
A31: Maintainability — Refers to how well a system can be modified to improve, correct or adapt to changes in the environment as well as requirements.
A32: 16 | B32: The decoupled codebase is well-structured, separating the Laravel REST API backend from the lonic Angular frontend for easy maintenance | C32: 1 | D32: 2 | E32: 4 | F32: 5 | G32: 3 | H32: =(5*I32+4*J32+3*K32+2*L32+1*M32)/SUM(I32:M32) -> 3 | I32: =COUNTIF(C32:G32,5) -> 1 | J32: =COUNTIF(C32:G32,4) -> 1 | K32: =COUNTIF(C32:G32,3) -> 1 | L32: =COUNTIF(C32:G32,2) -> 1 | M32: =COUNTIF(C32:G32,1) -> 1
A33: 17 | B33: System logs, user activity logs, and audit trails are easily accessible for administrative troubleshooting. | C33: 5 | D33: 1 | E33: 4 | F33: 5 | G33: 4 | H33: =(5*I33+4*J33+3*K33+2*L33+1*M33)/SUM(I33:M33) -> 3.8 | I33: =COUNTIF(C33:G33,5) -> 2 | J33: =COUNTIF(C33:G33,4) -> 2 | K33: =COUNTIF(C33:G33,3) -> 0 | L33: =COUNTIF(C33:G33,2) -> 0 | M33: =COUNTIF(C33:G33,1) -> 1
A34: 18 | B34: The modular architecture allows developers to calibrate specific parameters such as fare matrices and geofence boundaries independently. | C34: 4 | D34: 1 | E34: 2 | F34: 1 | G34: 2 | H34: =(5*I34+4*J34+3*K34+2*L34+1*M34)/SUM(I34:M34) -> 2 | I34: =COUNTIF(C34:G34,5) -> 0 | J34: =COUNTIF(C34:G34,4) -> 1 | K34: =COUNTIF(C34:G34,3) -> 0 | L34: =COUNTIF(C34:G34,2) -> 2 | M34: =COUNTIF(C34:G34,1) -> 2
A35: Category Weighted Mean — Maintainability | H35: =AVERAGE(H32:H34) -> 2.9333333
A36: Flexibility — The degree to which a product can be adapted to changes in its requirements, contexts of use or system environment.
A37: 19 | B37: The system architecture can be easily adjusted to accommodate changes in TODA dispatching rules and geofence radius settings. | C37: 5 | D37: 3 | E37: 4 | F37: 4 | G37: 4 | H37: =(5*I37+4*J37+3*K37+2*L37+1*M37)/SUM(I37:M37) -> 4 | I37: =COUNTIF(C37:G37,5) -> 1 | J37: =COUNTIF(C37:G37,4) -> 3 | K37: =COUNTIF(C37:G37,3) -> 1 | L37: =COUNTIF(C37:G37,2) -> 0 | M37: =COUNTIF(C37:G37,1) -> 0
A38: 20 | B38: The database structure and REST API can scale to support an expansion in subdivision coverage areas or additional transport terminals. | C38: 4 | D38: 4 | E38: 3 | F38: 4 | G38: 4 | H38: =(5*I38+4*J38+3*K38+2*L38+1*M38)/SUM(I38:M38) -> 3.8 | I38: =COUNTIF(C38:G38,5) -> 0 | J38: =COUNTIF(C38:G38,4) -> 4 | K38: =COUNTIF(C38:G38,3) -> 1 | L38: =COUNTIF(C38:G38,2) -> 0 | M38: =COUNTIF(C38:G38,1) -> 0
A39: 21 | B39: The MapLibre GL map configuration allows switching tile providers and styling layers without modifying core application logic. | C39: 5 | D39: 3 | E39: 3 | F39: 3 | G39: 3 | H39: =(5*I39+4*J39+3*K39+2*L39+1*M39)/SUM(I39:M39) -> 3.4 | I39: =COUNTIF(C39:G39,5) -> 1 | J39: =COUNTIF(C39:G39,4) -> 0 | K39: =COUNTIF(C39:G39,3) -> 4 | L39: =COUNTIF(C39:G39,2) -> 0 | M39: =COUNTIF(C39:G39,1) -> 0
A40: Category Weighted Mean — Flexibility | H40: =AVERAGE(H37:H39) -> 3.7333333
A41: Safety — The degree to which a product avoids a state in which human life, health, property, or the environment is endangered.
...

Sheet End-Users
A1: Assessment on the Quality of Using the System — For End-Users
A2: Scale: 5 = Strongly Agree (SA) | 4 = Agree (A) | 3 = Neutral (N) | 2 = Disagree (D) | 1 = Strongly Disagree (SD)
A3: Editable cells: yellow-shaded respondent score cells (R1–R30). Enter values 1–5 only. Sample data shown below. Add columns between R29 and R30 if respondents is greater than 30.
A5: Item No. | B5: Item Statement | C5: R1 | D5: R2 | E5: R3 | F5: R4 | G5: R5 | H5: R6 | I5: R7 | J5: R8 | K5: R9 | L5: R10 | M5: R11 | N5: R12 | O5: R13 | P5: R14 | Q5: R15 | R5: R16 | S5: R17 | T5: R18 | U5: R19 | V5: R20 | W5: R21 | X5: R22 | Y5: R23 | Z5: R24 | AA5: R25 | AB5: R26 | AC5: R27 | AD5: R28 | AE5: R29 | AF5: R30 | AG5: Weighted Mean | AH5: SA (5) | AI5: A (4) | AJ5: N (3) | AK5: D (2) | AL5: SD (1)
A6: Functional Suitability — The degree to which the system provides functions that meet stated and implied needs when used under specified conditions.
A7: 1 | B7: The application accurately fulfills its intended role for my daily transport needs (booking rides, queuing at the terminal, or administrative monitoring). | C7: 5 | D7: 5 | E7: 5 | F7: 5 | G7: 5 | H7: 5 | I7: 5 | J7: 5 | K7: 5 | L7: 4 | M7: 5 | N7: 5 | O7: 5 | P7: 4 | Q7: 4 | R7: 4 | S7: 3 | T7: 3 | U7: 5 | V7: 4 | W7: 5 | X7: 4 | Y7: 5 | Z7: 5 | AA7: 3 | AB7: 3 | AC7: 4 | AD7: 5 | AE7: 3 | AF7: 3 | AG7: =(5*AH7+4*AI7+3*AJ7+2*AK7+1*AL7)/SUM(AH7:AL7) -> 4.3666667 | AH7: =COUNTIF(C7:AF7,5) -> 17 | AI7: =COUNTIF(C7:AF7,4) -> 7 | AJ7: =COUNTIF(C7:AF7,3) -> 6 | AK7: =COUNTIF(C7:AF7,2) -> 0 | AL7: =COUNTIF(C7:AF7,1) -> 0
A8: 2 | B8: The live terminal queue and "Next-in-Line" status provide clear and accurate visibility of tricycle availability. | C8: 5 | D8: 5 | E8: 5 | F8: 5 | G8: 5 | H8: 5 | I8: 5 | J8: 5 | K8: 5 | L8: 4 | M8: 5 | N8: 5 | O8: 5 | P8: 5 | Q8: 4 | R8: 4 | S8: 5 | T8: 4 | U8: 5 | V8: 3 | W8: 5 | X8: 5 | Y8: 5 | Z8: 5 | AA8: 5 | AB8: 5 | AC8: 4 | AD8: 5 | AE8: 5 | AF8: 4 | AG8: =(5*AH8+4*AI8+3*AJ8+2*AK8+1*AL8)/SUM(AH8:AL8) -> 4.7333333 | AH8: =COUNTIF(C8:AF8,5) -> 23 | AI8: =COUNTIF(C8:AF8,4) -> 6 | AJ8: =COUNTIF(C8:AF8,3) -> 1 | AK8: =COUNTIF(C8:AF8,2) -> 0 | AL8: =COUNTIF(C8:AF8,1) -> 0
A9: 3 | B9: The system allows me to easily access and review my personal activity records (trip history, fare breakdown, or TODA compliance logs). | C9: 5 | D9: 5 | E9: 5 | F9: 5 | G9: 5 | H9: 5 | I9: 5 | J9: 5 | K9: 5 | L9: 3 | M9: 5 | N9: 5 | O9: 5 | P9: 5 | Q9: 4 | R9: 4 | S9: 4 | T9: 3 | U9: 5 | V9: 4 | W9: 5 | X9: 4 | Y9: 5 | Z9: 5 | AA9: 5 | AB9: 5 | AC9: 4 | AD9: 5 | AE9: 5 | AF9: 4 | AG9: =(5*AH9+4*AI9+3*AJ9+2*AK9+1*AL9)/SUM(AH9:AL9) -> 4.6333333 | AH9: =COUNTIF(C9:AF9,5) -> 21 | AI9: =COUNTIF(C9:AF9,4) -> 7 | AJ9: =COUNTIF(C9:AF9,3) -> 2 | AK9: =COUNTIF(C9:AF9,2) -> 0 | AL9: =COUNTIF(C9:AF9,1) -> 0
A10: Category Weighted Mean — Functional Suitability | AG10: =AVERAGE(AG7:AG9) -> 4.5777778
A11: Performance Efficiency — Relative to the number of resources used under stated conditions.
A12: 4 | B12: The Progressive Web Application loads quickly and operates smoothly on my smartphone without causing device sluggishness. | C12: 5 | D12: 5 | E12: 5 | F12: 5 | G12: 5 | H12: 5 | I12: 5 | J12: 5 | K12: 5 | L12: 5 | M12: 5 | N12: 5 | O12: 5 | P12: 4 | Q12: 4 | R12: 4 | S12: 3 | T12: 3 | U12: 5 | V12: 3 | W12: 5 | X12: 5 | Y12: 5 | Z12: 5 | AA12: 5 | AB12: 5 | AC12: 5 | AD12: 5 | AE12: 5 | AF12: 5 | AG12: =(5*AH12+4*AI12+3*AJ12+2*AK12+1*AL12)/SUM(AH12:AL12) -> 4.7 | AH12: =COUNTIF(C12:AF12,5) -> 24 | AI12: =COUNTIF(C12:AF12,4) -> 3 | AJ12: =COUNTIF(C12:AF12,3) -> 3 | AK12: =COUNTIF(C12:AF12,2) -> 0 | AL12: =COUNTIF(C12:AF12,1) -> 0
A13: 5 | B13: Real-time updates (ride alerts, dispatch notifications, and queue position changes) appear without noticeable delay. | C13: 5 | D13: 5 | E13: 5 | F13: 5 | G13: 5 | H13: 5 | I13: 5 | J13: 5 | K13: 5 | L13: 4 | M13: 5 | N13: 5 | O13: 5 | P13: 5 | Q13: 4 | R13: 4 | S13: 4 | T13: 4 | U13: 5 | V13: 4 | W13: 5 | X13: 5 | Y13: 5 | Z13: 5 | AA13: 5 | AB13: 5 | AC13: 5 | AD13: 5 | AE13: 5 | AF13: 5 | AG13: =(5*AH13+4*AI13+3*AJ13+2*AK13+1*AL13)/SUM(AH13:AL13) -> 4.8 | AH13: =COUNTIF(C13:AF13,5) -> 24 | AI13: =COUNTIF(C13:AF13,4) -> 6 | AJ13: =COUNTIF(C13:AF13,3) -> 0 | AK13: =COUNTIF(C13:AF13,2) -> 0 | AL13: =COUNTIF(C13:AF13,1) -> 0
A14: 6 | B14: The application runs efficiently in the background during active sessions without excessive battery consumption. | C14: 5 | D14: 5 | E14: 5 | F14: 5 | G14: 5 | H14: 5 | I14: 5 | J14: 5 | K14: 5 | L14: 3 | M14: 5 | N14: 5 | O14: 5 | P14: 5 | Q14: 3 | R14: 4 | S14: 3 | T14: 4 | U14: 5 | V14: 3 | W14: 5 | X14: 5 | Y14: 5 | Z14: 5 | AA14: 5 | AB14: 5 | AC14: 5 | AD14: 5 | AE14: 5 | AF14: 5 | AG14: =(5*AH14+4*AI14+3*AJ14+2*AK14+1*AL14)/SUM(AH14:AL14) -> 4.6666667 | AH14: =COUNTIF(C14:AF14,5) -> 24 | AI14: =COUNTIF(C14:AF14,4) -> 2 | AJ14: =COUNTIF(C14:AF14,3) -> 4 | AK14: =COUNTIF(C14:AF14,2) -> 0 | AL14: =COUNTIF(C14:AF14,1) -> 0
A15: Category Weighted Mean — Performance Efficiency | AG15: =AVERAGE(AG12:AG14) -> 4.7222222
A16: Interaction Capability — The degree to which a system can be interacted with by specified users to exchange information through the user interface to complete the intended task.
A17: 7 | B17: The user interface (buttons, input fields, navigation tabs) is intuitive and easy to use without requiring technical training. | C17: 5 | D17: 5 | E17: 5 | F17: 5 | G17: 4 | H17: 5 | I17: 5 | J17: 5 | K17: 5 | L17: 3 | M17: 5 | N17: 5 | O17: 4 | P17: 5 | Q17: 4 | R17: 3 | S17: 3 | T17: 4 | U17: 5 | V17: 2 | W17: 5 | X17: 5 | Y17: 5 | Z17: 5 | AA17: 5 | AB17: 5 | AC17: 5 | AD17: 5 | AE17: 5 | AF17: 4 | AG17: =(5*AH17+4*AI17+3*AJ17+2*AK17+1*AL17)/SUM(AH17:AL17) -> 4.5333333 | AH17: =COUNTIF(C17:AF17,5) -> 21 | AI17: =COUNTIF(C17:AF17,4) -> 5 | AJ17: =COUNTIF(C17:AF17,3) -> 3 | AK17: =COUNTIF(C17:AF17,2) -> 1 | AL17: =COUNTIF(C17:AF17,1) -> 0
A18: 8 | B18: The platform provides clear and instant on-screen feedback whenever I perform an action (e.g., booking a ride, accepting a dispatch, or uploading documents). | C18: 5 | D18: 5 | E18: 5 | F18: 5 | G18: 5 | H18: 5 | I18: 5 | J18: 5 | K18: 5 | L18: 4 | M18: 5 | N18: 5 | O18: 5 | P18: 5 | Q18: 3 | R18: 4 | S18: 4 | T18: 4 | U18: 5 | V18: 3 | W18: 5 | X18: 4 | Y18: 5 | Z18: 5 | AA18: 5 | AB18: 5 | AC18: 5 | AD18: 5 | AE18: 5 | AF18: 4 | AG18: =(5*AH18+4*AI18+3*AJ18+2*AK18+1*AL18)/SUM(AH18:AL18) -> 4.6666667 | AH18: =COUNTIF(C18:AF18,5) -> 22 | AI18: =COUNTIF(C18:AF18,4) -> 6 | AJ18: =COUNTIF(C18:AF18,3) -> 2 | AK18: =COUNTIF(C18:AF18,2) -> 0 | AL18: =COUNTIF(C18:AF18,1) -> 0
A19: 9 | B19: The text size, layout, and visual contrast make it effortless to read instructions and understand what action to take next. | C19: 3 | D19: 5 | E19: 4 | F19: 5 | G19: 4 | H19: 4 | I19: 4 | J19: 2 | K19: 4 | L19: 1 | M19: 4 | N19: 4 | O19: 3 | P19: 3 | Q19: 1 | R19: 1 | S19: 1 | T19: 2 | U19: 5 | V19: 1 | W19: 2 | X19: 2 | Y19: 4 | Z19: 3 | AA19: 5 | AB19: 5 | AC19: 4 | AD19: 5 | AE19: 3 | AF19: 3 | AG19: =(5*AH19+4*AI19+3*AJ19+2*AK19+1*AL19)/SUM(AH19:AL19) -> 3.2333333 | AH19: =COUNTIF(C19:AF19,5) -> 6 | AI19: =COUNTIF(C19:AF19,4) -> 9 | AJ19: =COUNTIF(C19:AF19,3) -> 6 | AK19: =COUNTIF(C19:AF19,2) -> 4 | AL19: =COUNTIF(C19:AF19,1) -> 5
A20: Category Weighted Mean — Interaction Capability | AG20: =AVERAGE(AG17:AG19) -> 4.1444444
A21: Reliability — The degree to which the system performs specified functions under specified conditions for a specified period of time.
A22: 10 | B22: The application remains stable and does not crash or freeze during active hailing and dispatching operations. | C22: 5 | D22: 5 | E22: 5 | F22: 5 | G22: 5 | H22: 5 | I22: 5 | J22: 5 | K22: 5 | L22: 4 | M22: 5 | N22: 5 | O22: 4 | P22: 4 | Q22: 3 | R22: 4 | S22: 3 | T22: 4 | U22: 5 | V22: 4 | W22: 5 | X22: 5 | Y22: 5 | Z22: 5 | AA22: 5 | AB22: 5 | AC22: 5 | AD22: 5 | AE22: 5 | AF22: 5 | AG22: =(5*AH22+4*AI22+3*AJ22+2*AK22+1*AL22)/SUM(AH22:AL22) -> 4.6666667 | AH22: =COUNTIF(C22:AF22,5) -> 22 | AI22: =COUNTIF(C22:AF22,4) -> 6 | AJ22: =COUNTIF(C22:AF22,3) -> 2 | AK22: =COUNTIF(C22:AF22,2) -> 0 | AL22: =COUNTIF(C22:AF22,1) -> 0
A23: 11 | B23: The automated queue algorithm maintains strict fairness, properly managing turn-taking and queue recovery when rides are canceled. | C23: 5 | D23: 5 | E23: 5 | F23: 5 | G23: 5 | H23: 5 | I23: 5 | J23: 5 | K23: 5 | L23: 3 | M23: 5 | N23: 5 | O23: 3 | P23: 5 | Q23: 3 | R23: 4 | S23: 3 | T23: 4 | U23: 5 | V23: 4 | W23: 5 | X23: 5 | Y23: 5 | Z23: 5 | AA23: 5 | AB23: 5 | AC23: 5 | AD23: 5 | AE23: 5 | AF23: 5 | AG23: =(5*AH23+4*AI23+3*AJ23+2*AK23+1*AL23)/SUM(AH23:AL23) -> 4.6333333 | AH23: =COUNTIF(C23:AF23,5) -> 23 | AI23: =COUNTIF(C23:AF23,4) -> 3 | AJ23: =COUNTIF(C23:AF23,3) -> 4 | AK23: =COUNTIF(C23:AF23,2) -> 0 | AL23: =COUNTIF(C23:AF23,1) -> 0
A24: 12 | B24: The system retains my current session and transaction state (queue slot or active ride request) even during brief cellular data or internet interruptions. | C24: 5 | D24: 5 | E24: 5 | F24: 5 | G24: 5 | H24: 5 | I24: 5 | J24: 5 | K24: 5 | L24: 4 | M24: 5 | N24: 5 | O24: 5 | P24: 5 | Q24: 5 | R24: 4 | S24: 4 | T24: 4 | U24: 5 | V24: 5 | W24: 5 | X24: 5 | Y24: 5 | Z24: 5 | AA24: 5 | AB24: 5 | AC24: 5 | AD24: 5 | AE24: 5 | AF24: 5 | AG24: =(5*AH24+4*AI24+3*AJ24+2*AK24+1*AL24)/SUM(AH24:AL24) -> 4.8666667 | AH24: =COUNTIF(C24:AF24,5) -> 26 | AI24: =COUNTIF(C24:AF24,4) -> 4 | AJ24: =COUNTIF(C24:AF24,3) -> 0 | AK24: =COUNTIF(C24:AF24,2) -> 0 | AL24: =COUNTIF(C24:AF24,1) -> 0
A25: Category Weighted Mean — Reliability | AG25: =AVERAGE(AG22:AG24) -> 4.7222222
A27: OVERALL WEIGHTED MEAN / TOTAL FREQUENCY (All Items) | AG27: =(AVERAGE(AG7:AG9)+AVERAGE(AG12:AG14)+AVERAGE(AG17:AG19)+AVERAGE(AG22:AG24))/4 -> 4.5416667 | AH27: =COUNTIF(C7:AF9,5)+COUNTIF(C12:AF14,5)+COUNTIF(C17:AF19,5)+COUNTIF(C22:AF24,5) -> 253 | AI27: =COUNTIF(C7:AF9,4)+COUNTIF(C12:AF14,4)+COUNTIF(C17:AF19,4)+COUNTIF(C22:AF24,4) -> 64 | AJ27: =COUNTIF(C7:AF9,3)+COUNTIF(C12:AF14,3)+COUNTIF(C17:AF19,3)+COUNTIF(C22:AF24,3) -> 33 | AK27: =COUNTIF(C7:AF9,2)+COUNTIF(C12:AF14,2)+COUNTIF(C17:AF19,2)+COUNTIF(C22:AF24,2) -> 5 | AL27: =COUNTIF(C7:AF9,1)+COUNTIF(C12:AF14,1)+COUNTIF(C17:AF19,1)+COUNTIF(C22:AF24,1) -> 5

Sheet APA Results - IT Experts
A1: Table 1
A2: Functional Suitability — The degree to which the system provides functions that meet stated and implied needs when used under specified conditions. (As Rated by IT Experts, N = 5)
A3: Item Statement | B3: Highly Suitable/ Efficient (5) | D3: Suitable/ Efficient (4) | F3: Moderately Suitable (3) | H3: Unsuitable/ Inefficient (2) | J3: Highly Unsuitable (1) | L3: Weighted Mean | M3: Qualitative Remarks
B4: f | C4: % | D4: f | E4: % | F4: f | G4: % | H4: f | I4: % | J4: f | K4: %
A5: The 35-meter geofencing triggers accurately log driver terminal entries and exits while deactivating coordinate tracking during active transit. | B5: ='IT Experts'!I7 -> 5 | C5: ='IT Experts'!I7/COUNT('IT Experts'!$C7:$G7) -> 1 | D5: ='IT Experts'!J7 -> 0 | E5: ='IT Experts'!J7/COUNT('IT Experts'!$C7:$G7) -> 0 | F5: ='IT Experts'!K7 -> 0 | G5: ='IT Experts'!K7/COUNT('IT Experts'!$C7:$G7) -> 0 | H5: ='IT Experts'!L7 -> 0 | I5: ='IT Experts'!L7/COUNT('IT Experts'!$C7:$G7) -> 0 | J5: ='IT Experts'!M7 -> 0 | K5: ='IT Experts'!M7/COUNT('IT Experts'!$C7:$G7) -> 0 | L5: ='IT Experts'!H7 -> 5 | M5: =IF('IT Experts'!H7>='Scoring Rubrics'!$A$6,'Scoring Rubrics'!$C$6,IF('IT Experts'!H7>='Scoring Rubrics'!$A$7,'Scoring Rubrics'!$C$7,IF('IT Experts'!H7>='Scoring Rubrics'!$A$8,'Scoring Rubrics'!$C$8,IF('IT Experts'!H7>='Scoring Rubrics'!$A$9,'Scoring Rubrics'!$C$9,'Scoring Rubrics'!$C$10)))) -> Highly Suitable
A6: The priority-based queue algorithm accurately sequences drivers in first-in, first-served order and immediately recovers dispatch positions upon cancellations. | B6: ='IT Experts'!I8 -> 4 | C6: ='IT Experts'!I8/COUNT('IT Experts'!$C8:$G8) -> 0.8 | D6: ='IT Experts'!J8 -> 1 | E6: ='IT Experts'!J8/COUNT('IT Experts'!$C8:$G8) -> 0.2 | F6: ='IT Experts'!K8 -> 0 | G6: ='IT Experts'!K8/COUNT('IT Experts'!$C8:$G8) -> 0 | H6: ='IT Experts'!L8 -> 0 | I6: ='IT Experts'!L8/COUNT('IT Experts'!$C8:$G8) -> 0 | J6: ='IT Experts'!M8 -> 0 | K6: ='IT Experts'!M8/COUNT('IT Experts'!$C8:$G8) -> 0 | L6: ='IT Experts'!H8 -> 4.8 | M6: =IF('IT Experts'!H8>='Scoring Rubrics'!$A$6,'Scoring Rubrics'!$C$6,IF('IT Experts'!H8>='Scoring Rubrics'!$A$7,'Scoring Rubrics'!$C$7,IF('IT Experts'!H8>='Scoring Rubrics'!$A$8,'Scoring Rubrics'!$C$8,IF('IT Experts'!H8>='Scoring Rubrics'!$A$9,'Scoring Rubrics'!$C$9,'Scoring Rubrics'!$C$10)))) -> Highly Suitable
A7: The TODA Admin and Super Admin dashboards successfully execute manual queue overrides, driver removals, and compliance verifications without corrupting the dispatch sequence. | B7: ='IT Experts'!I9 -> 4 | C7: ='IT Experts'!I9/COUNT('IT Experts'!$C9:$G9) -> 0.8 | D7: ='IT Experts'!J9 -> 1 | E7: ='IT Experts'!J9/COUNT('IT Experts'!$C9:$G9) -> 0.2 | F7: ='IT Experts'!K9 -> 0 | G7: ='IT Experts'!K9/COUNT('IT Experts'!$C9:$G9) -> 0 | H7: ='IT Experts'!L9 -> 0 | I7: ='IT Experts'!L9/COUNT('IT Experts'!$C9:$G9) -> 0 | J7: ='IT Experts'!M9 -> 0 | K7: ='IT Experts'!M9/COUNT('IT Experts'!$C9:$G9) -> 0 | L7: ='IT Experts'!H9 -> 4.8 | M7: =IF('IT Experts'!H9>='Scoring Rubrics'!$A$6,'Scoring Rubrics'!$C$6,IF('IT Experts'!H9>='Scoring Rubrics'!$A$7,'Scoring Rubrics'!$C$7,IF('IT Experts'!H9>='Scoring Rubrics'!$A$8,'Scoring Rubrics'!$C$8,IF('IT Experts'!H9>='Scoring Rubrics'!$A$9,'Scoring Rubrics'!$C$9,'Scoring Rubrics'!$C$10)))) -> Highly Suitable
A8: Category Weighted Mean | L8: ='IT Experts'!H10 -> 4.8666667 | M8: =IF('IT Experts'!H10>='Scoring Rubrics'!$A$6,'Scoring Rubrics'!$C$6,IF('IT Experts'!H10>='Scoring Rubrics'!$A$7,'Scoring Rubrics'!$C$7,IF('IT Experts'!H10>='Scoring Rubrics'!$A$8,'Scoring Rubrics'!$C$8,IF('IT Experts'!H10>='Scoring Rubrics'!$A$9,'Scoring Rubrics'!$C$9,'Scoring Rubrics'!$C$10)))) -> Highly Suitable
A9: Note. n = 5. Weighted mean = Σ(f × rating) ÷ n. Interpretation based on the scoring rubric for functional suitability: 4.21 – 5.00 = Highly Suitable; 3.41 – 4.20 = Suitable; 2.61 – 3.40 = Somewhat Suitable; 1.81 – 2.60 = Unsuitable; 1.00 – 1.80 = Highly Unsuitable.
A12: Table 2
A13: Performance Efficiency — Relative to the number of resources used under stated conditions. (As Rated by IT Experts, N = 5)
A14: Item Statement | B14: Highly Suitable/ Efficient (5) | D14: Suitable/ Efficient (4) | F14: Moderately Suitable (3) | H14: Unsuitable/ Inefficient (2) | J14: Highly Unsuitable (1) | L14: Weighted Mean | M14: Qualitative Remarks
B15: f | C15: % | D15: f | E15: % | F15: f | G15: % | H15: f | I15: % | J15: f | K15: %
A16: The Laravel Reverb event-driven architecture broadcasts real-time map updates and queue transitions within the acceptable latency threshold. | B16: ='IT Experts'!I12 -> 0 | C16: ='IT Experts'!I12/COUNT('IT Experts'!$C12:$G12) -> 0 | D16: ='IT Experts'!J12 -> 4 | E16: ='IT Experts'!J12/COUNT('IT Experts'!$C12:$G12) -> 0.8 | F16: ='IT Experts'!K12 -> 1 | G16: ='IT Experts'!K12/COUNT('IT Experts'!$C12:$G12) -> 0.2 | H16: ='IT Experts'!L12 -> 0 | I16: ='IT Experts'!L12/COUNT('IT Experts'!$C12:$G12) -> 0 | J16: ='IT Experts'!M12 -> 0 | K16: ='IT Experts'!M12/COUNT('IT Experts'!$C12:$G12) -> 0 | L16: ='IT Experts'!H12 -> 3.8 | M16: =IF('IT Experts'!H12>='Scoring Rubrics'!$A$14,'Scoring Rubrics'!$C$14,IF('IT Experts'!H12>='Scoring Rubrics'!$A$15,'Scoring Rubrics'!$C$15,IF('IT Experts'!H12>='Scoring Rubrics'!$A$16,'Scoring Rubrics'!$C$16,IF('IT Experts'!H12>='Scoring Rubrics'!$A$17,'Scoring Rubrics'!$C$17,'Scoring Rubrics'!$C$18)))) -> Efficient
A17: The MapLibre GL mapping engine renders hardware-accelerated vector map layers and driver positions smoothly on mobile devices. | B17: ='IT Experts'!I13 -> 1 | C17: ='IT Experts'!I13/COUNT('IT Experts'!$C13:$G13) -> 0.2 | D17: ='IT Experts'!J13 -> 4 | E17: ='IT Experts'!J13/COUNT('IT Experts'!$C13:$G13) -> 0.8 | F17: ='IT Experts'!K13 -> 0 | G17: ='IT Experts'!K13/COUNT('IT Experts'!$C13:$G13) -> 0 | H17: ='IT Experts'!L13 -> 0 | I17: ='IT Experts'!L13/COUNT('IT Experts'!$C13:$G13) -> 0 | J17: ='IT Experts'!M13 -> 0 | K17: ='IT Experts'!M13/COUNT('IT Experts'!$C13:$G13) -> 0 | L17: ='IT Experts'!H13 -> 4.2 | M17: =IF('IT Experts'!H13>='Scoring Rubrics'!$A$14,'Scoring Rubrics'!$C$14,IF('IT Experts'!H13>='Scoring Rubrics'!$A$15,'Scoring Rubrics'!$C$15,IF('IT Experts'!H13>='Scoring Rubrics'!$A$16,'Scoring Rubrics'!$C$16,IF('IT Experts'!H13>='Scoring Rubrics'!$A$17,'Scoring Rubrics'!$C$17,'Scoring Rubrics'!$C$18)))) -> Efficient
A18: The backend database queries and WebSocket listeners consume minimal server resources during peak simulated traffic. | B18: ='IT Experts'!I14 -> 1 | C18: ='IT Experts'!I14/COUNT('IT Experts'!$C14:$G14) -> 0.2 | D18: ='IT Experts'!J14 -> 4 | E18: ='IT Experts'!J14/COUNT('IT Experts'!$C14:$G14) -> 0.8 | F18: ='IT Experts'!K14 -> 0 | G18: ='IT Experts'!K14/COUNT('IT Experts'!$C14:$G14) -> 0 | H18: ='IT Experts'!L14 -> 0 | I18: ='IT Experts'!L14/COUNT('IT Experts'!$C14:$G14) -> 0 | J18: ='IT Experts'!M14 -> 0 | K18: ='IT Experts'!M14/COUNT('IT Experts'!$C14:$G14) -> 0 | L18: ='IT Experts'!H14 -> 4.2 | M18: =IF('IT Experts'!H14>='Scoring Rubrics'!$A$14,'Scoring Rubrics'!$C$14,IF('IT Experts'!H14>='Scoring Rubrics'!$A$15,'Scoring Rubrics'!$C$15,IF('IT Experts'!H14>='Scoring Rubrics'!$A$16,'Scoring Rubrics'!$C$16,IF('IT Experts'!H14>='Scoring Rubrics'!$A$17,'Scoring Rubrics'!$C$17,'Scoring Rubrics'!$C$18)))) -> Efficient
A19: Category Weighted Mean | L19: ='IT Experts'!H15 -> 4.0666667 | M19: =IF('IT Experts'!H15>='Scoring Rubrics'!$A$14,'Scoring Rubrics'!$C$14,IF('IT Experts'!H15>='Scoring Rubrics'!$A$15,'Scoring Rubrics'!$C$15,IF('IT Experts'!H15>='Scoring Rubrics'!$A$16,'Scoring Rubrics'!$C$16,IF('IT Experts'!H15>='Scoring Rubrics'!$A$17,'Scoring Rubrics'!$C$17,'Scoring Rubrics'!$C$18)))) -> Efficient
A20: Note. n = 5. Weighted mean = Σ(f × rating) ÷ n. Interpretation based on the scoring rubric for performance efficiency: 4.21 – 5.00 = Highly Efficient; 3.41 – 4.20 = Efficient; 2.61 – 3.40 = Less Efficient; 1.81 – 2.60 = Inefficient; 1.00 – 1.80 = Highly Inefficient.
A23: Table 3
A24: Compatibility — The degree to which a software system can exchange information with other systems whilst sharing the same software and hardware. (As Rated by IT Experts, N = 5)
A25: Item Statement | B25: Highly Suitable/ Efficient (5) | D25: Suitable/ Efficient (4) | F25: Moderately Suitable (3) | H25: Unsuitable/ Inefficient (2) | J25: Highly Unsuitable (1) | L25: Weighted Mean | M25: Qualitative Remarks
B26: f | C26: % | D26: f | E26: % | F26: f | G26: % | H26: f | I26: % | J26: f | K26: %
A27: The Progressive Web Application built with the lonic Framework functions seamlessly across different mobile browsers and operating systems. | B27: ='IT Experts'!I17 -> 0 | C27: ='IT Experts'!I17/COUNT('IT Experts'!$C17:$G17) -> 0 | D27: ='IT Experts'!J17 -> 2 | E27: ='IT Experts'!J17/COUNT('IT Experts'!$C17:$G17) -> 0.4 | F27: ='IT Experts'!K17 -> 3 | G27: ='IT Experts'!K17/COUNT('IT Experts'!$C17:$G17) -> 0.6 | H27: ='IT Experts'!L17 -> 0 | I27: ='IT Experts'!L17/COUNT('IT Experts'!$C17:$G17) -> 0 | J27: ='IT Experts'!M17 -> 0 | K27: ='IT Experts'!M17/COUNT('IT Experts'!$C17:$G17) -> 0 | L27: ='IT Experts'!H17 -> 3.4 | M27: =IF('IT Experts'!H17>='Scoring Rubrics'!$A$22,'Scoring Rubrics'!$C$22,IF('IT Experts'!H17>='Scoring Rubrics'!$A$23,'Scoring Rubrics'!$C$23,IF('IT Experts'!H17>='Scoring Rubrics'!$A$24,'Scoring Rubrics'!$C$24,IF('IT Experts'!H17>='Scoring Rubrics'!$A$25,'Scoring Rubrics'!$C$25,'Scoring Rubrics'!$C$26)))) -> Somewhat Compatible
A28: The system integrates well with device-level HTML5 Geolocation APIs and background Web Push notification services. | B28: ='IT Experts'!I18 -> 2 | C28: ='IT Experts'!I18/COUNT('IT Experts'!$C18:$G18) -> 0.4 | D28: ='IT Experts'!J18 -> 2 | E28: ='IT Experts'!J18/COUNT('IT Experts'!$C18:$G18) -> 0.4 | F28: ='IT Experts'!K18 -> 1 | G28: ='IT Experts'!K18/COUNT('IT Experts'!$C18:$G18) -> 0.2 | H28: ='IT Experts'!L18 -> 0 | I28: ='IT Experts'!L18/COUNT('IT Experts'!$C18:$G18) -> 0 | J28: ='IT Experts'!M18 -> 0 | K28: ='IT Experts'!M18/COUNT('IT Experts'!$C18:$G18) -> 0 | L28: ='IT Experts'!H18 -> 4.2 | M28: =IF('IT Experts'!H18>='Scoring Rubrics'!$A$22,'Scoring Rubrics'!$C$22,IF('IT Experts'!H18>='Scoring Rubrics'!$A$23,'Scoring Rubrics'!$C$23,IF('IT Experts'!H18>='Scoring Rubrics'!$A$24,'Scoring Rubrics'!$C$24,IF('IT Experts'!H18>='Scoring Rubrics'!$A$25,'Scoring Rubrics'!$C$25,'Scoring Rubrics'!$C$26)))) -> Compatible
A29: The user interface layout automatically adapts to varying mobile screen sizes and resolutions without visual breakage. | B29: ='IT Experts'!I19 -> 0 | C29: ='IT Experts'!I19/COUNT('IT Experts'!$C19:$G19) -> 0 | D29: ='IT Experts'!J19 -> 4 | E29: ='IT Experts'!J19/COUNT('IT Experts'!$C19:$G19) -> 0.8 | F29: ='IT Experts'!K19 -> 1 | G29: ='IT Experts'!K19/COUNT('IT Experts'!$C19:$G19) -> 0.2 | H29: ='IT Experts'!L19 -> 0 | I29: ='IT Experts'!L19/COUNT('IT Experts'!$C19:$G19) -> 0 | J29: ='IT Experts'!M19 -> 0 | K29: ='IT Experts'!M19/COUNT('IT Experts'!$C19:$G19) -> 0 | L29: ='IT Experts'!H19 -> 3.8 | M29: =IF('IT Experts'!H19>='Scoring Rubrics'!$A$22,'Scoring Rubrics'!$C$22,IF('IT Experts'!H19>='Scoring Rubrics'!$A$23,'Scoring Rubrics'!$C$23,IF('IT Experts'!H19>='Scoring Rubrics'!$A$24,'Scoring Rubrics'!$C$24,IF('IT Experts'!H19>='Scoring Rubrics'!$A$25,'Scoring Rubrics'!$C$25,'Scoring Rubrics'!$C$26)))) -> Compatible
A30: Category Weighted Mean | L30: ='IT Experts'!H20 -> 3.8 | M30: =IF('IT Experts'!H20>='Scoring Rubrics'!$A$22,'Scoring Rubrics'!$C$22,IF('IT Experts'!H20>='Scoring Rubrics'!$A$23,'Scoring Rubrics'!$C$23,IF('IT Experts'!H20>='Scoring Rubrics'!$A$24,'Scoring Rubrics'!$C$24,IF('IT Experts'!H20>='Scoring Rubrics'!$A$25,'Scoring Rubrics'!$C$25,'Scoring Rubrics'!$C$26)))) -> Compatible
A31: Note. n = 5. Weighted mean = Σ(f × rating) ÷ n. Interpretation based on the scoring rubric for compatibility: 4.21 – 5.00 = Highly Compatible; 3.41 – 4.20 = Compatible; 2.61 – 3.40 = Somewhat Compatible; 1.81 – 2.60 = Less Compatible; 1.00 – 1.80 = Not Compatible.
A34: Table 4
A35: Interaction Capability — The degree to which a system can be interacted with by specified users to exchange information through the user interface to complete the intended task. (As Rated by IT Experts, N = 5)
A36: Item Statement | B36: Highly Suitable/ Efficient (5) | D36: Suitable/ Efficient (4) | F36: Moderately Suitable (3) | H36: Unsuitable/ Inefficient (2) | J36: Highly Unsuitable (1) | L36: Weighted Mean | M36: Qualitative Remarks
B37: f | C37: % | D37: f | E37: % | F37: f | G37: % | H37: f | I37: % | J37: f | K37: %
A38: The user interfaces for the passenger, driver, TODA admin, and super admin portals are intuitive and easy to navigate. | B38: ='IT Experts'!I22 -> 2 | C38: ='IT Experts'!I22/COUNT('IT Experts'!$C22:$G22) -> 0.4 | D38: ='IT Experts'!J22 -> 2 | E38: ='IT Experts'!J22/COUNT('IT Experts'!$C22:$G22) -> 0.4 | F38: ='IT Experts'!K22 -> 1 | G38: ='IT Experts'!K22/COUNT('IT Experts'!$C22:$G22) -> 0.2 | H38: ='IT Experts'!L22 -> 0 | I38: ='IT Experts'!L22/COUNT('IT Experts'!$C22:$G22) -> 0 | J38: ='IT Experts'!M22 -> 0 | K38: ='IT Experts'!M22/COUNT('IT Experts'!$C22:$G22) -> 0 | L38: ='IT Experts'!H22 -> 4.2 | M38: =IF('IT Experts'!H22>='Scoring Rubrics'!$A$30,'Scoring Rubrics'!$C$30,IF('IT Experts'!H22>='Scoring Rubrics'!$A$31,'Scoring Rubrics'!$C$31,IF('IT Experts'!H22>='Scoring Rubrics'!$A$32,'Scoring Rubrics'!$C$32,IF('IT Experts'!H22>='Scoring Rubrics'!$A$33,'Scoring Rubrics'!$C$33,'Scoring Rubrics'!$C$34)))) -> Interactive
A39: The system provides clear and immediate visual and audio feedback upon successful actions and dispatch events. | B39: ='IT Experts'!I23 -> 2 | C39: ='IT Experts'!I23/COUNT('IT Experts'!$C23:$G23) -> 0.4 | D39: ='IT Experts'!J23 -> 3 | E39: ='IT Experts'!J23/COUNT('IT Experts'!$C23:$G23) -> 0.6 | F39: ='IT Experts'!K23 -> 0 | G39: ='IT Experts'!K23/COUNT('IT Experts'!$C23:$G23) -> 0 | H39: ='IT Experts'!L23 -> 0 | I39: ='IT Experts'!L23/COUNT('IT Experts'!$C23:$G23) -> 0 | J39: ='IT Experts'!M23 -> 0 | K39: ='IT Experts'!M23/COUNT('IT Experts'!$C23:$G23) -> 0 | L39: ='IT Experts'!H23 -> 4.4 | M39: =IF('IT Experts'!H23>='Scoring Rubrics'!$A$30,'Scoring Rubrics'!$C$30,IF('IT Experts'!H23>='Scoring Rubrics'!$A$31,'Scoring Rubrics'!$C$31,IF('IT Experts'!H23>='Scoring Rubrics'!$A$32,'Scoring Rubrics'!$C$32,IF('IT Experts'!H23>='Scoring Rubrics'!$A$33,'Scoring Rubrics'!$C$33,'Scoring Rubrics'!$C$34)))) -> Highly Interactive
A40: Input forms include proper validation and display clear, specific error messages when invalid data is entered. | B40: ='IT Experts'!I24 -> 2 | C40: ='IT Experts'!I24/COUNT('IT Experts'!$C24:$G24) -> 0.4 | D40: ='IT Experts'!J24 -> 3 | E40: ='IT Experts'!J24/COUNT('IT Experts'!$C24:$G24) -> 0.6 | F40: ='IT Experts'!K24 -> 0 | G40: ='IT Experts'!K24/COUNT('IT Experts'!$C24:$G24) -> 0 | H40: ='IT Experts'!L24 -> 0 | I40: ='IT Experts'!L24/COUNT('IT Experts'!$C24:$G24) -> 0 | J40: ='IT Experts'!M24 -> 0 | K40: ='IT Experts'!M24/COUNT('IT Experts'!$C24:$G24) -> 0 | L40: ='IT Experts'!H24 -> 4.4 | M40: =IF('IT Experts'!H24>='Scoring Rubrics'!$A$30,'Scoring Rubrics'!$C$30,IF('IT Experts'!H24>='Scoring Rubrics'!$A$31,'Scoring Rubrics'!$C$31,IF('IT Experts'!H24>='Scoring Rubrics'!$A$32,'Scoring Rubrics'!$C$32,IF('IT Experts'!H24>='Scoring Rubrics'!$A$33,'Scoring Rubrics'!$C$33,'Scoring Rubrics'!$C$34)))) -> Highly Interactive
A41: Category Weighted Mean | L41: ='IT Experts'!H25 -> 4.3333333 | M41: =IF('IT Experts'!H25>='Scoring Rubrics'!$A$30,'Scoring Rubrics'!$C$30,IF('IT Experts'!H25>='Scoring Rubrics'!$A$31,'Scoring Rubrics'!$C$31,IF('IT Experts'!H25>='Scoring Rubrics'!$A$32,'Scoring Rubrics'!$C$32,IF('IT Experts'!H25>='Scoring Rubrics'!$A$33,'Scoring Rubrics'!$C$33,'Scoring Rubrics'!$C$34)))) -> Highly Interactive
A42: Note. n = 5. Weighted mean = Σ(f × rating) ÷ n. Interpretation based on the scoring rubric for interaction capability: 4.21 – 5.00 = Highly Interactive; 3.41 – 4.20 = Interactive; 2.61 – 3.40 = Less Interactive; 1.81 – 2.60 = Poorly Interactive; 1.00 – 1.80 = Non-Interactive.
A45: Table 5
A46: Reliability — The degree to which the system performs specified functions under specified conditions for a specified period of time. (As Rated by IT Experts, N = 5)
A47: Item Statement | B47: Highly Suitable/ Efficient (5) | D47: Suitable/ Efficient (4) | F47: Moderately Suitable (3) | H47: Unsuitable/ Inefficient (2) | J47: Highly Unsuitable (1) | L47: Weighted Mean | M47: Qualitative Remarks
B48: f | C48: % | D48: f | E48: % | F48: f | G48: % | H48: f | I48: % | J48: f | K48: %
...

Sheet APA Results - End-Users
A1: Table 10
A2: Functional Suitability — The degree to which the system provides functions that meet stated and implied needs when used under specified conditions. (As Rated by End-Users, N = 30) | O2: Note:
A3: Item Statement | B3: Strongly Agree (5) | D3: Agree (4) | F3: Neutral (3) | H3: Disagree (2) | J3: Strongly Disagree (1) | L3: Weighted Mean | M3: Qualitative Remarks | O3: Copy and paste these tables in word file for Chapter 3
B4: f | C4: % | D4: f | E4: % | F4: f | G4: % | H4: f | I4: % | J4: f | K4: %
A5: The application accurately fulfills its intended role for my daily transport needs (booking rides, queuing at the terminal, or administrative monitoring). | B5: ='End-Users'!AH7 -> 17 | C5: ='End-Users'!AH7/COUNT('End-Users'!$C7:$AF7) -> 0.56666667 | D5: ='End-Users'!AI7 -> 7 | E5: ='End-Users'!AI7/COUNT('End-Users'!$C7:$AF7) -> 0.23333333 | F5: ='End-Users'!AJ7 -> 6 | G5: ='End-Users'!AJ7/COUNT('End-Users'!$C7:$AF7) -> 0.2 | H5: ='End-Users'!AK7 -> 0 | I5: ='End-Users'!AK7/COUNT('End-Users'!$C7:$AF7) -> 0 | J5: ='End-Users'!AL7 -> 0 | K5: ='End-Users'!AL7/COUNT('End-Users'!$C7:$AF7) -> 0 | L5: ='End-Users'!AG7 -> 4.3666667 | M5: =IF('End-Users'!AG7>='Scoring Rubrics'!$A$6,'Scoring Rubrics'!$C$6,IF('End-Users'!AG7>='Scoring Rubrics'!$A$7,'Scoring Rubrics'!$C$7,IF('End-Users'!AG7>='Scoring Rubrics'!$A$8,'Scoring Rubrics'!$C$8,IF('End-Users'!AG7>='Scoring Rubrics'!$A$9,'Scoring Rubrics'!$C$9,'Scoring Rubrics'!$C$10)))) -> Highly Suitable
A6: The live terminal queue and "Next-in-Line" status provide clear and accurate visibility of tricycle availability. | B6: ='End-Users'!AH8 -> 23 | C6: ='End-Users'!AH8/COUNT('End-Users'!$C8:$AF8) -> 0.76666667 | D6: ='End-Users'!AI8 -> 6 | E6: ='End-Users'!AI8/COUNT('End-Users'!$C8:$AF8) -> 0.2 | F6: ='End-Users'!AJ8 -> 1 | G6: ='End-Users'!AJ8/COUNT('End-Users'!$C8:$AF8) -> 0.033333333 | H6: ='End-Users'!AK8 -> 0 | I6: ='End-Users'!AK8/COUNT('End-Users'!$C8:$AF8) -> 0 | J6: ='End-Users'!AL8 -> 0 | K6: ='End-Users'!AL8/COUNT('End-Users'!$C8:$AF8) -> 0 | L6: ='End-Users'!AG8 -> 4.7333333 | M6: =IF('End-Users'!AG8>='Scoring Rubrics'!$A$6,'Scoring Rubrics'!$C$6,IF('End-Users'!AG8>='Scoring Rubrics'!$A$7,'Scoring Rubrics'!$C$7,IF('End-Users'!AG8>='Scoring Rubrics'!$A$8,'Scoring Rubrics'!$C$8,IF('End-Users'!AG8>='Scoring Rubrics'!$A$9,'Scoring Rubrics'!$C$9,'Scoring Rubrics'!$C$10)))) -> Highly Suitable
A7: The system allows me to easily access and review my personal activity records (trip history, fare breakdown, or TODA compliance logs). | B7: ='End-Users'!AH9 -> 21 | C7: ='End-Users'!AH9/COUNT('End-Users'!$C9:$AF9) -> 0.7 | D7: ='End-Users'!AI9 -> 7 | E7: ='End-Users'!AI9/COUNT('End-Users'!$C9:$AF9) -> 0.23333333 | F7: ='End-Users'!AJ9 -> 2 | G7: ='End-Users'!AJ9/COUNT('End-Users'!$C9:$AF9) -> 0.066666667 | H7: ='End-Users'!AK9 -> 0 | I7: ='End-Users'!AK9/COUNT('End-Users'!$C9:$AF9) -> 0 | J7: ='End-Users'!AL9 -> 0 | K7: ='End-Users'!AL9/COUNT('End-Users'!$C9:$AF9) -> 0 | L7: ='End-Users'!AG9 -> 4.6333333 | M7: =IF('End-Users'!AG9>='Scoring Rubrics'!$A$6,'Scoring Rubrics'!$C$6,IF('End-Users'!AG9>='Scoring Rubrics'!$A$7,'Scoring Rubrics'!$C$7,IF('End-Users'!AG9>='Scoring Rubrics'!$A$8,'Scoring Rubrics'!$C$8,IF('End-Users'!AG9>='Scoring Rubrics'!$A$9,'Scoring Rubrics'!$C$9,'Scoring Rubrics'!$C$10)))) -> Highly Suitable
A8: Category Weighted Mean | L8: ='End-Users'!AG10 -> 4.5777778 | M8: =IF('End-Users'!AG10>='Scoring Rubrics'!$A$6,'Scoring Rubrics'!$C$6,IF('End-Users'!AG10>='Scoring Rubrics'!$A$7,'Scoring Rubrics'!$C$7,IF('End-Users'!AG10>='Scoring Rubrics'!$A$8,'Scoring Rubrics'!$C$8,IF('End-Users'!AG10>='Scoring Rubrics'!$A$9,'Scoring Rubrics'!$C$9,'Scoring Rubrics'!$C$10)))) -> Highly Suitable
A9: Note. n = 30. Weighted mean = Σ(f × rating) ÷ n. Interpretation based on the scoring rubric for functional suitability: 4.21 – 5.00 = Highly Suitable; 3.41 – 4.20 = Suitable; 2.61 – 3.40 = Somewhat Suitable; 1.81 – 2.60 = Unsuitable; 1.00 – 1.80 = Highly Unsuitable.
A12: Table 11
A13: Performance Efficiency — Relative to the number of resources used under stated conditions. (As Rated by End-Users, N = 30)
A14: Item Statement | B14: Strongly Agree (5) | D14: Agree (4) | F14: Neutral (3) | H14: Disagree (2) | J14: Strongly Disagree (1) | L14: Weighted Mean | M14: Qualitative Remarks
B15: f | C15: % | D15: f | E15: % | F15: f | G15: % | H15: f | I15: % | J15: f | K15: %
A16: The Progressive Web Application loads quickly and operates smoothly on my smartphone without causing device sluggishness. | B16: ='End-Users'!AH12 -> 24 | C16: ='End-Users'!AH12/COUNT('End-Users'!$C12:$AF12) -> 0.8 | D16: ='End-Users'!AI12 -> 3 | E16: ='End-Users'!AI12/COUNT('End-Users'!$C12:$AF12) -> 0.1 | F16: ='End-Users'!AJ12 -> 3 | G16: ='End-Users'!AJ12/COUNT('End-Users'!$C12:$AF12) -> 0.1 | H16: ='End-Users'!AK12 -> 0 | I16: ='End-Users'!AK12/COUNT('End-Users'!$C12:$AF12) -> 0 | J16: ='End-Users'!AL12 -> 0 | K16: ='End-Users'!AL12/COUNT('End-Users'!$C12:$AF12) -> 0 | L16: ='End-Users'!AG12 -> 4.7 | M16: =IF('End-Users'!AG12>='Scoring Rubrics'!$A$14,'Scoring Rubrics'!$C$14,IF('End-Users'!AG12>='Scoring Rubrics'!$A$15,'Scoring Rubrics'!$C$15,IF('End-Users'!AG12>='Scoring Rubrics'!$A$16,'Scoring Rubrics'!$C$16,IF('End-Users'!AG12>='Scoring Rubrics'!$A$17,'Scoring Rubrics'!$C$17,'Scoring Rubrics'!$C$18)))) -> Highly Efficient
A17: Real-time updates (ride alerts, dispatch notifications, and queue position changes) appear without noticeable delay. | B17: ='End-Users'!AH13 -> 24 | C17: ='End-Users'!AH13/COUNT('End-Users'!$C13:$AF13) -> 0.8 | D17: ='End-Users'!AI13 -> 6 | E17: ='End-Users'!AI13/COUNT('End-Users'!$C13:$AF13) -> 0.2 | F17: ='End-Users'!AJ13 -> 0 | G17: ='End-Users'!AJ13/COUNT('End-Users'!$C13:$AF13) -> 0 | H17: ='End-Users'!AK13 -> 0 | I17: ='End-Users'!AK13/COUNT('End-Users'!$C13:$AF13) -> 0 | J17: ='End-Users'!AL13 -> 0 | K17: ='End-Users'!AL13/COUNT('End-Users'!$C13:$AF13) -> 0 | L17: ='End-Users'!AG13 -> 4.8 | M17: =IF('End-Users'!AG13>='Scoring Rubrics'!$A$14,'Scoring Rubrics'!$C$14,IF('End-Users'!AG13>='Scoring Rubrics'!$A$15,'Scoring Rubrics'!$C$15,IF('End-Users'!AG13>='Scoring Rubrics'!$A$16,'Scoring Rubrics'!$C$16,IF('End-Users'!AG13>='Scoring Rubrics'!$A$17,'Scoring Rubrics'!$C$17,'Scoring Rubrics'!$C$18)))) -> Highly Efficient
A18: The application runs efficiently in the background during active sessions without excessive battery consumption. | B18: ='End-Users'!AH14 -> 24 | C18: ='End-Users'!AH14/COUNT('End-Users'!$C14:$AF14) -> 0.8 | D18: ='End-Users'!AI14 -> 2 | E18: ='End-Users'!AI14/COUNT('End-Users'!$C14:$AF14) -> 0.066666667 | F18: ='End-Users'!AJ14 -> 4 | G18: ='End-Users'!AJ14/COUNT('End-Users'!$C14:$AF14) -> 0.13333333 | H18: ='End-Users'!AK14 -> 0 | I18: ='End-Users'!AK14/COUNT('End-Users'!$C14:$AF14) -> 0 | J18: ='End-Users'!AL14 -> 0 | K18: ='End-Users'!AL14/COUNT('End-Users'!$C14:$AF14) -> 0 | L18: ='End-Users'!AG14 -> 4.6666667 | M18: =IF('End-Users'!AG14>='Scoring Rubrics'!$A$14,'Scoring Rubrics'!$C$14,IF('End-Users'!AG14>='Scoring Rubrics'!$A$15,'Scoring Rubrics'!$C$15,IF('End-Users'!AG14>='Scoring Rubrics'!$A$16,'Scoring Rubrics'!$C$16,IF('End-Users'!AG14>='Scoring Rubrics'!$A$17,'Scoring Rubrics'!$C$17,'Scoring Rubrics'!$C$18)))) -> Highly Efficient
A19: Category Weighted Mean | L19: ='End-Users'!AG15 -> 4.7222222 | M19: =IF('End-Users'!AG15>='Scoring Rubrics'!$A$14,'Scoring Rubrics'!$C$14,IF('End-Users'!AG15>='Scoring Rubrics'!$A$15,'Scoring Rubrics'!$C$15,IF('End-Users'!AG15>='Scoring Rubrics'!$A$16,'Scoring Rubrics'!$C$16,IF('End-Users'!AG15>='Scoring Rubrics'!$A$17,'Scoring Rubrics'!$C$17,'Scoring Rubrics'!$C$18)))) -> Highly Efficient
A20: Note. n = 30. Weighted mean = Σ(f × rating) ÷ n. Interpretation based on the scoring rubric for performance efficiency: 4.21 – 5.00 = Highly Efficient; 3.41 – 4.20 = Efficient; 2.61 – 3.40 = Less Efficient; 1.81 – 2.60 = Inefficient; 1.00 – 1.80 = Highly Inefficient.
A23: Table 12
A24: Interaction Capability — The degree to which a system can be interacted with by specified users to exchange information through the user interface to complete the intended task. (As Rated by End-Users, N = 30)
A25: Item Statement | B25: Strongly Agree (5) | D25: Agree (4) | F25: Neutral (3) | H25: Disagree (2) | J25: Strongly Disagree (1) | L25: Weighted Mean | M25: Qualitative Remarks
B26: f | C26: % | D26: f | E26: % | F26: f | G26: % | H26: f | I26: % | J26: f | K26: %
A27: The user interface (buttons, input fields, navigation tabs) is intuitive and easy to use without requiring technical training. | B27: ='End-Users'!AH17 -> 21 | C27: ='End-Users'!AH17/COUNT('End-Users'!$C17:$AF17) -> 0.7 | D27: ='End-Users'!AI17 -> 5 | E27: ='End-Users'!AI17/COUNT('End-Users'!$C17:$AF17) -> 0.16666667 | F27: ='End-Users'!AJ17 -> 3 | G27: ='End-Users'!AJ17/COUNT('End-Users'!$C17:$AF17) -> 0.1 | H27: ='End-Users'!AK17 -> 1 | I27: ='End-Users'!AK17/COUNT('End-Users'!$C17:$AF17) -> 0.033333333 | J27: ='End-Users'!AL17 -> 0 | K27: ='End-Users'!AL17/COUNT('End-Users'!$C17:$AF17) -> 0 | L27: ='End-Users'!AG17 -> 4.5333333 | M27: =IF('End-Users'!AG17>='Scoring Rubrics'!$A$30,'Scoring Rubrics'!$C$30,IF('End-Users'!AG17>='Scoring Rubrics'!$A$31,'Scoring Rubrics'!$C$31,IF('End-Users'!AG17>='Scoring Rubrics'!$A$32,'Scoring Rubrics'!$C$32,IF('End-Users'!AG17>='Scoring Rubrics'!$A$33,'Scoring Rubrics'!$C$33,'Scoring Rubrics'!$C$34)))) -> Highly Interactive
A28: The platform provides clear and instant on-screen feedback whenever I perform an action (e.g., booking a ride, accepting a dispatch, or uploading documents). | B28: ='End-Users'!AH18 -> 22 | C28: ='End-Users'!AH18/COUNT('End-Users'!$C18:$AF18) -> 0.73333333 | D28: ='End-Users'!AI18 -> 6 | E28: ='End-Users'!AI18/COUNT('End-Users'!$C18:$AF18) -> 0.2 | F28: ='End-Users'!AJ18 -> 2 | G28: ='End-Users'!AJ18/COUNT('End-Users'!$C18:$AF18) -> 0.066666667 | H28: ='End-Users'!AK18 -> 0 | I28: ='End-Users'!AK18/COUNT('End-Users'!$C18:$AF18) -> 0 | J28: ='End-Users'!AL18 -> 0 | K28: ='End-Users'!AL18/COUNT('End-Users'!$C18:$AF18) -> 0 | L28: ='End-Users'!AG18 -> 4.6666667 | M28: =IF('End-Users'!AG18>='Scoring Rubrics'!$A$30,'Scoring Rubrics'!$C$30,IF('End-Users'!AG18>='Scoring Rubrics'!$A$31,'Scoring Rubrics'!$C$31,IF('End-Users'!AG18>='Scoring Rubrics'!$A$32,'Scoring Rubrics'!$C$32,IF('End-Users'!AG18>='Scoring Rubrics'!$A$33,'Scoring Rubrics'!$C$33,'Scoring Rubrics'!$C$34)))) -> Highly Interactive
A29: The text size, layout, and visual contrast make it effortless to read instructions and understand what action to take next. | B29: ='End-Users'!AH19 -> 6 | C29: ='End-Users'!AH19/COUNT('End-Users'!$C19:$AF19) -> 0.2 | D29: ='End-Users'!AI19 -> 9 | E29: ='End-Users'!AI19/COUNT('End-Users'!$C19:$AF19) -> 0.3 | F29: ='End-Users'!AJ19 -> 6 | G29: ='End-Users'!AJ19/COUNT('End-Users'!$C19:$AF19) -> 0.2 | H29: ='End-Users'!AK19 -> 4 | I29: ='End-Users'!AK19/COUNT('End-Users'!$C19:$AF19) -> 0.13333333 | J29: ='End-Users'!AL19 -> 5 | K29: ='End-Users'!AL19/COUNT('End-Users'!$C19:$AF19) -> 0.16666667 | L29: ='End-Users'!AG19 -> 3.2333333 | M29: =IF('End-Users'!AG19>='Scoring Rubrics'!$A$30,'Scoring Rubrics'!$C$30,IF('End-Users'!AG19>='Scoring Rubrics'!$A$31,'Scoring Rubrics'!$C$31,IF('End-Users'!AG19>='Scoring Rubrics'!$A$32,'Scoring Rubrics'!$C$32,IF('End-Users'!AG19>='Scoring Rubrics'!$A$33,'Scoring Rubrics'!$C$33,'Scoring Rubrics'!$C$34)))) -> Less Interactive
A30: Category Weighted Mean | L30: ='End-Users'!AG20 -> 4.1444444 | M30: =IF('End-Users'!AG20>='Scoring Rubrics'!$A$30,'Scoring Rubrics'!$C$30,IF('End-Users'!AG20>='Scoring Rubrics'!$A$31,'Scoring Rubrics'!$C$31,IF('End-Users'!AG20>='Scoring Rubrics'!$A$32,'Scoring Rubrics'!$C$32,IF('End-Users'!AG20>='Scoring Rubrics'!$A$33,'Scoring Rubrics'!$C$33,'Scoring Rubrics'!$C$34)))) -> Interactive
A31: Note. n = 30. Weighted mean = Σ(f × rating) ÷ n. Interpretation based on the scoring rubric for interaction capability: 4.21 – 5.00 = Highly Interactive; 3.41 – 4.20 = Interactive; 2.61 – 3.40 = Less Interactive; 1.81 – 2.60 = Poorly Interactive; 1.00 – 1.80 = Non-Interactive.
A34: Table 13
A35: Reliability — The degree to which the system performs specified functions under specified conditions for a specified period of time. (As Rated by End-Users, N = 30)
A36: Item Statement | B36: Strongly Agree (5) | D36: Agree (4) | F36: Neutral (3) | H36: Disagree (2) | J36: Strongly Disagree (1) | L36: Weighted Mean | M36: Qualitative Remarks
B37: f | C37: % | D37: f | E37: % | F37: f | G37: % | H37: f | I37: % | J37: f | K37: %
A38: The application remains stable and does not crash or freeze during active hailing and dispatching operations. | B38: ='End-Users'!AH22 -> 22 | C38: ='End-Users'!AH22/COUNT('End-Users'!$C22:$AF22) -> 0.73333333 | D38: ='End-Users'!AI22 -> 6 | E38: ='End-Users'!AI22/COUNT('End-Users'!$C22:$AF22) -> 0.2 | F38: ='End-Users'!AJ22 -> 2 | G38: ='End-Users'!AJ22/COUNT('End-Users'!$C22:$AF22) -> 0.066666667 | H38: ='End-Users'!AK22 -> 0 | I38: ='End-Users'!AK22/COUNT('End-Users'!$C22:$AF22) -> 0 | J38: ='End-Users'!AL22 -> 0 | K38: ='End-Users'!AL22/COUNT('End-Users'!$C22:$AF22) -> 0 | L38: ='End-Users'!AG22 -> 4.6666667 | M38: =IF('End-Users'!AG22>='Scoring Rubrics'!$A$38,'Scoring Rubrics'!$C$38,IF('End-Users'!AG22>='Scoring Rubrics'!$A$39,'Scoring Rubrics'!$C$39,IF('End-Users'!AG22>='Scoring Rubrics'!$A$40,'Scoring Rubrics'!$C$40,IF('End-Users'!AG22>='Scoring Rubrics'!$A$41,'Scoring Rubrics'!$C$41,'Scoring Rubrics'!$C$42)))) -> Highly Reliable
A39: The automated queue algorithm maintains strict fairness, properly managing turn-taking and queue recovery when rides are canceled. | B39: ='End-Users'!AH23 -> 23 | C39: ='End-Users'!AH23/COUNT('End-Users'!$C23:$AF23) -> 0.76666667 | D39: ='End-Users'!AI23 -> 3 | E39: ='End-Users'!AI23/COUNT('End-Users'!$C23:$AF23) -> 0.1 | F39: ='End-Users'!AJ23 -> 4 | G39: ='End-Users'!AJ23/COUNT('End-Users'!$C23:$AF23) -> 0.13333333 | H39: ='End-Users'!AK23 -> 0 | I39: ='End-Users'!AK23/COUNT('End-Users'!$C23:$AF23) -> 0 | J39: ='End-Users'!AL23 -> 0 | K39: ='End-Users'!AL23/COUNT('End-Users'!$C23:$AF23) -> 0 | L39: ='End-Users'!AG23 -> 4.6333333 | M39: =IF('End-Users'!AG23>='Scoring Rubrics'!$A$38,'Scoring Rubrics'!$C$38,IF('End-Users'!AG23>='Scoring Rubrics'!$A$39,'Scoring Rubrics'!$C$39,IF('End-Users'!AG23>='Scoring Rubrics'!$A$40,'Scoring Rubrics'!$C$40,IF('End-Users'!AG23>='Scoring Rubrics'!$A$41,'Scoring Rubrics'!$C$41,'Scoring Rubrics'!$C$42)))) -> Highly Reliable
A40: The system retains my current session and transaction state (queue slot or active ride request) even during brief cellular data or internet interruptions. | B40: ='End-Users'!AH24 -> 26 | C40: ='End-Users'!AH24/COUNT('End-Users'!$C24:$AF24) -> 0.86666667 | D40: ='End-Users'!AI24 -> 4 | E40: ='End-Users'!AI24/COUNT('End-Users'!$C24:$AF24) -> 0.13333333 | F40: ='End-Users'!AJ24 -> 0 | G40: ='End-Users'!AJ24/COUNT('End-Users'!$C24:$AF24) -> 0 | H40: ='End-Users'!AK24 -> 0 | I40: ='End-Users'!AK24/COUNT('End-Users'!$C24:$AF24) -> 0 | J40: ='End-Users'!AL24 -> 0 | K40: ='End-Users'!AL24/COUNT('End-Users'!$C24:$AF24) -> 0 | L40: ='End-Users'!AG24 -> 4.8666667 | M40: =IF('End-Users'!AG24>='Scoring Rubrics'!$A$38,'Scoring Rubrics'!$C$38,IF('End-Users'!AG24>='Scoring Rubrics'!$A$39,'Scoring Rubrics'!$C$39,IF('End-Users'!AG24>='Scoring Rubrics'!$A$40,'Scoring Rubrics'!$C$40,IF('End-Users'!AG24>='Scoring Rubrics'!$A$41,'Scoring Rubrics'!$C$41,'Scoring Rubrics'!$C$42)))) -> Highly Reliable
